Workbook

Sheet ENTREGABLES
B2: objetivo: | C2: lograr la implementación de todo el programa en 8 meses
B3: quien va a ganar: | C3: menor costo
B5: 1 | C5: Tablero donde se vea el plan de trabajo general inicio - fin del programa
B6: 2 | C6: tablero donde se vea el plan de trabajo por site
B7: 3 | C7: tabla de uso de recursos por sitio y general para el programa. Quiero poder modificar esa tabla
B8: 4 | C8: poder guardar el escenario
B9: 5 | C9: que me de un resumen de costos para el programa (por escenario), costo por site, por tipo de recurso
B11: rubrica de calificación | H11: Maxima | I11: Ejemplo
H12: =+H13+H14 -> 1 | I12: =+I13+I14 -> 0.84375
C13: 8 meses + menor costo | H13: 0.5 | I13: 0.5
C14: Rúbrica | H14: 0.5 | I14: =+I22 -> 0.34375
H15: Maxima | I15: Ejemplo
C16: Dashboard principal | H16: 4 | I16: 2
C17: Guardar y comparar escenarios | H17: 4 | I17: 3
C18: Explicacion y entendimiento de cada pestaña del excel | H18: 4 | I18: 3
C19: Calidad de la información. Correcta, bien etiquetada, sin basura ni errores. | H19: 2 | I19: 1
C20: Visual / UI. Limpio, con jerarquía y legible. | H20: 2 | I20: 2
H21: =+SUM(H16:H20) -> 16 | I21: =+SUM(I16:I20) -> 11
H22: 0.5 | I22: =+I21/H21*H22 -> 0.34375

Sheet Sites Master
A1: Country | B1: Brewery | C1: Cluster | D1: Capacity (Mio HL) | E1: Production (Mio HL) | F1: Distribution Volume (K HL) | G1: Line Capacity | H1: Production Lines | I1: # Warehouses | J1: Warehouse Area | K1: Occupation LV | L1: Aisles Identification | M1: Box Identification | N1: Control Tower | O1: T2/MKP/KA | P1: Forklifts in Logistics | Q1: HC Forklifts | R1: WIFI State | S1: Tablets | T1: Counting Devices
A2: Mexico | B2: Site 01 | C2: 2 | D2: 3.72 | E2: 1.43 | F2: 6400 | G2: 0.3844086 | H2: 3 | I2: 1 | J2: 9100 | K2: 0.815 | L2: 0.89 | M2: Yes | N2: No | O2: No | P2: 18 | Q2: 38 | R2: 0.85 | S2: 15 | T2: 5
A3: Mexico | B3: Site 02 | C3: 2 | D3: 6.46 | E3: 4.77 | F3: 11160 | G3: 0.73839009 | H3: 6 | I3: 2 | J3: 15572 | K3: 0.94 | L3: 0 | M3: No | N3: No | O3: No | P3: 30 | Q3: 90 | R3: 0 | S3: 29 | T3: 6
A4: Mexico | B4: Site 03 | C4: 2 | D4: 6.46 | E4: 4.77 | F4: 11160 | G4: 0.73839009 | H4: 6 | I4: 2 | J4: 15572 | K4: 0.94 | L4: 0 | M4: No | N4: No | O4: No | P4: 30 | Q4: 90 | R4: 0 | S4: 29 | T4: 6
A5: Mexico | B5: Site 04 | C5: 2 | D5: 6.59 | E5: 4.58 | F5: 11520 | G5: 0.69499241 | H5: 5 | I5: 2 | J5: 17742 | K5: 0.78 | L5: 0 | M5: No | N5: Yes | O5: No | P5: 37 | Q5: 80 | R5: 0 | S5: 15 | T5: 4
A6: Mexico | B6: Site 05 | C6: 3 | D6: 2.75 | E6: 2.12 | F6: 6848 | G6: 0.77090909 | H6: 2 | I6: 3 | J6: 5239 | K6: 0.855 | L6: 0.9 | M6: Yes | N6: No | O6: Yes | P6: 14 | Q6: 42 | R6: 0 | S6: 14 | T6: 4
A7: Mexico | B7: Site 06 | C7: 1 | D7: 13.2 | E7: 12.19 | F7: 29946 | G7: 0.92348485 | H7: 9 | I7: 2 | J7: 36333 | K7: 1 | L7: 0.93 | M7: Yes | N7: Yes | O7: Yes | P7: 76 | Q7: 213 | R7: 0 | S7: 85 | T7: 8
A8: Mexico | B8: Site 07 | C8: 2 | D8: 4.77 | E8: 3.82 | F8: 9900 | G8: 0.80083857 | H8: 4 | I8: 1 | J8: 14897 | K8: 1.05 | L8: 0 | M8: No | N8: No | O8: Yes | P8: 32 | Q8: 75 | R8: 0 | S8: 32 | T8: 6
A9: Colombia | B9: Site 08 | C9: 1 | D9: 14.262348 | E9: 14.221547 | F9: 11189 | G9: 0.9971393 | H9: 3 | I9: 1 | J9: 28576 | K9: 1.04 | L9: 1 | M9: Yes | N9: Yes | O9: Yes | P9: 32 | Q9: 117 | R9: 1 | S9: 40 | T9: 5
A10: Colombia | B10: Site 09 | C10: 2 | D10: 7.9588732 | E10: 3.0928813 | F10: 1822.3038 | G10: 0.38860794 | H10: 4 | I10: 1 | J10: 14097 | K10: 0.88 | L10: 0.5 | M10: Yes | N10: Yes | O10: Yes | P10: 10 | Q10: 32 | R10: 0.7 | S10: 20 | T10: 4
A11: Colombia | B11: Site 10 | C11: 1 | D11: 13.689521 | E11: 10.316546 | F11: 11164.56 | G11: 0.75360897 | H11: 10 | I11: 4 | J11: 13978 | K11: 0.96 | L11: 0.8 | M11: No | N11: Yes | O11: Yes | P11: 62 | Q11: 169 | R11: 0.5 | S11: 55 | T11: 7
A12: Colombia | B12: Site 11 | C12: 3 | D12: 3.9803505 | E12: 3.4122615 | F12: 2911.3283 | G12: 0.85727664 | H12: 4 | I12: 3 | J12: 4684 | K12: 0.84 | L12: 0.8 | M12: No | N12: No | O12: No | P12: 17 | Q12: 42 | R12: 0.6 | S12: 16 | T12: 3
A13: Colombia | B13: Site 12 | C13: 4 | D13: 2.1681612 | E13: 0.72307515 | F13: 699.07032 | G13: 0.33349695 | H13: 2 | I13: 1 | J13: 3797 | K13: 0.8 | L13: 0.8 | M13: No | N13: No | O13: No | P13: 4 | Q13: 15 | R13: 0.7 | S13: 5 | T13: 3
... A16: Colombia | B16: Site 15 | C16: 2 | D16: 5.0027996 | E16: 4.5090292 | F16: 4946.467 | G16: 0.90130118 | H16: 5 | I16: 3 | J16: 9601 | K16: 1.05 | L16: 0.6 | M16: No | N16: Yes | O16: No | P16: 19 | Q16: 54 | R16: 0.7 | S16: 18 | T16: 4

Sheet Financials (USD)
A1: Country | B1: Brewery | C1: Benefits per month | D1: Implementation Costs | E1: Devices | F1: Forklift Structure | G1: Warehouse Signage | H1: Labels | I1: Costs without Labelers & WiFi | J1: Label Printers / Labelers | K1: Manual Labeling | L1: WiFi Full | M1: WiFi Full Optimized | N1: WiFi Prioritized
A2: Mexico | B2: Site 01 | C2: 18511 | D2: 15000 | E2: 0 | F2: 6668.7957 | G2: 11370.371 | H2: 14425.153 | I2: =SUM(D2:H2) -> 47464.32 | J2: 7144.76 | K2: 0 | L2: 44451 | M2: 43451 | N2: 0
A3: Mexico | B3: Site 02 | C3: 26878 | D3: 15000 | E3: 70212.869 | F3: 9262.2162 | G3: 27796.938 | H3: 21152.792 | I3: =SUM(D3:H3) -> 143424.82 | J3: 81930.072 | K3: 142702.7 | L3: 287249 | M3: 220687 | N3: 110343.5
A4: Mexico | B4: Site 03 | C4: 61087 | D4: 25000 | E4: 84255.443 | F4: 11114.659 | G4: 23591.833 | H4: 18886.421 | I4: =SUM(D4:H4) -> 162848.36 | J4: 212307.9 | K4: 259459.46 | L4: 378909 | M4: 157740 | N4: 112671.43
A5: Mexico | B5: Site 04 | C5: 70898 | D5: 25000 | E5: 103915.05 | F5: 13708.08 | G5: 44202.766 | H5: 19286.813 | I5: =SUM(D5:H5) -> 206112.71 | J5: 184000.18 | K5: 220540.54 | L5: 411279 | M5: 368914 | N5: 230571.25
A6: Mexico | B6: Site 05 | C6: 14809 | D6: 15000 | E6: 0 | F6: 5927.8184 | G6: 10505.161 | H6: 11709.581 | I6: =SUM(D6:H6) -> 43142.561 | J6: 73600.072 | K6: 103783.78 | L6: 219880 | M6: 206497 | N6: 77436.375
A7: Mexico | B7: Site 06 | C7: 76636 | D7: 35000 | E7: 213447.12 | F7: 28157.137 | G7: 43677.876 | H7: 49482.424 | I7: =SUM(D7:H7) -> 369764.56 | J7: 302730.29 | K7: 376216.22 | L7: 523835 | M7: 297466 | N7: 220345.19
A8: Mexico | B8: Site 07 | C8: 30543 | D8: 25000 | E8: 98298.017 | F8: 12967.103 | G8: 39945.634 | H8: 13220.495 | I8: =SUM(D8:H8) -> 189431.25 | J8: 147200.14 | K8: 181621.62 | L8: 277152 | M8: 123137 | N8: 94720.769
A9: Colombia | B9: Site 08 | C9: 70420 | D9: 50000 | E9: 0 | F9: =9600*0 -> 0 | G9: =27945*0 -> 0 | H9: =34200*0 -> 0 | I9: =SUM(D9:H9) -> 50000 | J9: 0 | K9: 0 | L9: 0 | M9: 0 | N9: 0
A10: Colombia | B10: Site 09 | C10: 15920 | D10: 15000 | E10: 0 | F10: 3600 | G10: 12547 | H10: 3600 | I10: =SUM(D10:H10) -> 34747 | J10: 0 | K10: 0 | L10: 133781 | M10: 115803 | N10: 100862
A11: Colombia | B11: Site 10 | C11: 90320 | D11: 25000 | E11: 0 | F11: 15600 | G11: 57883 | H11: 8100 | I11: =SUM(D11:H11) -> 106583 | J11: 308459.68 | K11: 0 | L11: 487872 | M11: 364795 | N11: 154945.83
A12: Colombia | B12: Site 11 | C12: 24480 | D12: 15000 | E12: 0 | F12: 5560 | G12: 15273 | H12: 4500 | I12: =SUM(D12:H12) -> 40333 | J12: 176263 | K12: 0 | L12: 180753 | M12: 185549 | N12: 94573.812
A13: Colombia | B13: Site 12 | C13: 10180 | D13: 5000 | E13: 0 | F13: 1440 | G13: 3746 | H13: 1800 | I13: =SUM(D13:H13) -> 11986 | J13: 88131 | K13: 0 | L13: 116598 | M13: 73392 | N13: 43642.316
A14: Colombia | B14: Site 13 | C14: 109140 | D14: 50000 | E14: 369489 | F14: 44000 | G14: 73532 | H14: 20700 | I14: =SUM(D14:H14) -> 557721 | J14: 1189773 | K14: 0 | L14: 333663 | M14: 267903 | N14: 136549.42
A15: Colombia | B15: Site 14 | C15: 56820 | D15: 35000 | E15: 0 | F15: 18560 | G15: 58580 | H15: 9000 | I15: =SUM(D15:H15) -> 121140 | J15: 925379 | K15: 0 | L15: 319639 | M15: 286043 | N15: 121496.1
A16: Colombia | B16: Site 15 | C16: 27560 | D16: 15000 | E16: 0 | F16: 5320 | G16: 20351 | H16: 3600 | I16: =SUM(D16:H16) -> 44271 | J16: 88131 | K16: 0 | L16: 139767 | M16: 134417 | N16: 79930.635

Sheet Resource Master
A1: Role | B1: Work Mode | C1: Can Multitask | D1: Internal or External | E1: Fixed or Flexible Cost | F1: Average Monthly Cost (MXN) | G1: Actual | H1: Escenario 1
A2: Solution Architect | B2: Remote | C2: Yes | D2: Internal | E2: Fixed | F2: 36000 | G2: 1 | H2: 5 | N2: Go Live | O2: Post
A3: Warehouse Manager Org A | B3: Hybrid | C3: Yes | D3: Internal | E3: Fixed | F3: 35000 | G3: 1 | H3: 5
A4: Project Manager Country B | B4: Hybrid | C4: Partial | D4: Internal | E4: Fixed | F4: 25000 | G4: 1 | H4: 5
A5: Project Manager Country A | B5: Hybrid | C5: Partial | D5: Internal | E5: Fixed | F5: 25000 | G5: 1 | H5: 5
A6: Change Management Lead | B6: Onsite | C6: No | D6: Internal | E6: Fixed | F6: 16000 | G6: 1 | H6: 5
A7: Change Management Lead | B7: Onsite | C7: No | D7: External | E7: Fixed | F7: 16000 | G7: 1 | H7: 5
A8: Infrastructure Lead | B8: Onsite | C8: No | D8: Internal | E8: Fixed | F8: 42000 | G8: 1 | H8: 5
A9: Infrastructure Lead | B9: Onsite | C9: No | D9: External | E9: Flexible | F9: 43000 | G9: 1 | H9: 5
A10: Functional Lead | B10: Onsite | C10: No | D10: Internal | E10: Fixed | F10: 35000 | G10: 1 | H10: 5
A11: Functional Lead | B11: Onsite | C11: No | D11: External | E11: Flexible | F11: 35000 | G11: 1 | H11: 5
A12: SAP Integrations Lead | B12: Remote | C12: Yes | D12: Internal | E12: Fixed | F12: 62000 | G12: 1 | H12: 5
A13: SAP Integrations Specialist | B13: Remote | C13: Yes | D13: Internal | E13: Flexible | F13: 55000 | G13: 1 | H13: 5
A14: Azure Lead | B14: Remote | C14: Yes | D14: Internal | E14: Fixed | F14: 48000 | G14: 1 | H14: 5
... A19: Support Lead | B19: Remote | C19: Yes | D19: External | E19: Flexible | F19: 22000 | G19: 2 | H19: 5

Sheet Implementation Phases
A1: Cluster | B1: Phase | C1: Sequence | D1: Deployment Maturity | E1: Duration in Weeks
A2: 1 | B2: Site Readiness | C2: 1 | D2: A | E2: 5
A3: 1 | B3: Design Adaptation | C3: 2 | D3: A | E3: 2
A4: 1 | B4: Functional Review | C4: 3 | D4: A | E4: 1
A5: 1 | B5: UAT | C5: 4 | D5: A | E5: 2
A6: 1 | B6: Training | C6: 5 | D6: A | E6: 3
A7: 1 | B7: DIALT | C7: 6 | D7: A | E7: 1
A8: 1 | B8: Go Live | C8: 7 | D8: A | E8: 1
A9: 1 | B9: Hypercare | C9: 8 | D9: A | E9: 4
A10: 2 | B10: Site Readiness | C10: 1 | D10: A | E10: 4
A11: 2 | B11: Design Adaptation | C11: 2 | D11: A | E11: 1
A12: 2 | B12: Functional Review | C12: 3 | D12: A | E12: 1
A13: 2 | B13: UAT | C13: 4 | D13: A | E13: 2
... A65: 4 | B65: Hypercare | C65: 8 | D65: B | E65: 3

Sheet Phase-Resource Allocation
A1: Cluster | B1: Phase | C1: Role | D1: Capacity Consumption
A2: 1 | B2: Site Readiness | C2: Infrastructure Lead | D2: 1
A3: 1 | B3: Site Readiness | C3: SAP Integrations Lead | D3: 0.5
A4: 1 | B4: Design Adaptation | C4: Solution Architect | D4: 1
A5: 1 | B5: Design Adaptation | C5: SAP Integrations Lead | D5: 0.5
A6: 1 | B6: Design Adaptation | C6: SAP Integrations Specialist | D6: 0.5
A7: 1 | B7: Design Adaptation | C7: Azure Lead | D7: 0.5
A8: 1 | B8: Design Adaptation | C8: Azure Specialist | D8: 0.5
A9: 1 | B9: Design Adaptation | C9: Testing Lead | D9: 1
A10: 1 | B10: Design Adaptation | C10: Functional Lead | D10: 1
A11: 1 | B11: Design Adaptation | C11: Trainers | D11: 1
A12: 1 | B12: Design Adaptation | C12: Infrastructure Lead | D12: 1
A13: 1 | B13: Design Adaptation | C13: Functional Lead Vendor A | D13: 1
... A187: 3 | B187: Hypercare | C187: Functional Lead Vendor A | D187: 0.5

Sheet 00_README
B2: SIMULADOR WMS - GUIA DEL ARCHIVO
B4: QUE ES ESTE ARCHIVO
B5: Simulador de escenarios para la implementacion de un programa WMS en 15 sites (7 en Mexico, 8 en Colombia). Construido sobre las pestanas originales del archivo (ENTREGABLES, Sites Master, Financials (USD), Resource Master, Implementation Phases, Phase-Resource Allocation), que no fueron alteradas.
B6: Todo el simulador es 100% formulas: no hay valores fijos que representen resultados. Cambiar cualquier input en 01_INPUTS recalcula en cadena el cronograma (02_SCHEDULE), los recursos (03_RESOURCES), los costos (04_COSTS), el tablero (05_DASHBOARD), la vista por site (06_SITE_VIEW) y la comparacion de escenarios (07_SCENARIOS).
B8: RELACION ENTRE LAS PESTANAS ORIGINALES
B9: Sites Master.Cluster + 01_INPUTS.Deployment Maturity -> Implementation Phases (Cluster, Phase, Deployment Maturity) -> Duration in Weeks por fase.
B10: Sites Master.Cluster -> Phase-Resource Allocation (Cluster, Phase) -> Role + Capacity Consumption (recursos requeridos por fase).
B11: Phase-Resource Allocation.Role -> Resource Master.Role (sumando las variantes Interno/Externo del mismo rol) -> Average Monthly Cost (MXN) y headcount disponible (Actual / Escenario 1).
B12: Sites Master.Brewery (nombre del site) -> Financials (USD).Brewery -> Benefits per month, Implementation Costs, Devices, Forklift Structure, Warehouse Signage, Labels (suman 'Costs without Labelers & WiFi'), mas las opciones alternativas de etiquetado (Label Printers/Labelers o Manual Labeling) y de WiFi (Full, Full Optimized, Prioritized) que se eligen en 01_INPUTS.
B13: ENTREGABLES define el objetivo (8 meses) y el criterio de exito (menor costo entre los que cumplen); ambos estan parametrizados en 01_INPUTS y en la regla de recomendacion de 07_SCENARIOS.
B15: FLUJO DE USO
B16: 1) Ajuste los parametros en 01_INPUTS (nombre del escenario, fecha de inicio, Deployment Maturity, sites en paralelo, fuente de recursos, metodo de etiquetado, estrategia de WiFi, prioridad de sites, recursos disponibles por rol).
... B39: 07_SCENARIOS: tabla comparativa de escenarios y la recomendacion (cumple 8 meses + menor costo).

Sheet 01_INPUTS
AA1: ZONA DE CALCULO INTERNO (listas de validacion) - no editar manualmente
B2: SIMULADOR WMS - 01_INPUTS (parametros editables del escenario) | AA2: Deployment Maturity | AB2: Roles unicos | AC2: Fuente recursos | AD2: Metodo etiquetado | AE2: Estrategia WiFi
B3: Las celdas en AZUL son editables. Cambiar cualquiera de estos valores recalcula todo el simulador (Schedule, Resources, Costs, Dashboard, Scenarios). | AA3: ='Implementation Phases'!$D$2 -> A | AB3: ='Resource Master'!$A$2 -> Solution Architect | AC3: ='Resource Master'!$G$1 -> Actual | AD3: ='Financials (USD)'!$J$1 -> Label Printers / Labelers | AE3: ='Financials (USD)'!$L$1 -> WiFi Full
AA4: {=IFERROR(INDEX('Implementation Phases'!$D$2:$D$65,MATCH(0,COUNTIF($AA$3:AA3,'Implementation Phases'!$D$2:$D$65),0)),"")} -> B | AB4: {=IFERROR(INDEX('Resource Master'!$A$2:$A$19,MATCH(0,COUNTIF($AB$3:AB3,'Resource Master'!$A$2:$A$19),0)),"")} -> Warehouse Manager Org A | AC4: ='Resource Master'!$H$1 -> Escenario 1 | AD4: ='Financials (USD)'!$K$1 -> Manual Labeling | AE4: ='Financials (USD)'!$M$1 -> WiFi Full Optimized
B5: PARAMETROS GENERALES DEL ESCENARIO | AB5: {=IFERROR(INDEX('Resource Master'!$A$2:$A$19,MATCH(0,COUNTIF($AB$3:AB4,'Resource Master'!$A$2:$A$19),0)),"")} -> Project Manager Country B | AE5: ='Financials (USD)'!$N$1 -> WiFi Prioritized
B6: Nombre del escenario | C6: ="Escenario Base" -> Escenario Base | AB6: {=IFERROR(INDEX('Resource Master'!$A$2:$A$19,MATCH(0,COUNTIF($AB$3:AB5,'Resource Master'!$A$2:$A$19),0)),"")} -> Project Manager Country A
B7: Fecha de inicio del programa | C7: =DATE(2026,8,17) -> 46251 | AB7: {=IFERROR(INDEX('Resource Master'!$A$2:$A$19,MATCH(0,COUNTIF($AB$3:AB6,'Resource Master'!$A$2:$A$19),0)),"")} -> Change Management Lead
B8: Deployment Maturity (A o B, fuente: Implementation Phases) | C8: ="A" -> A | AB8: {=IFERROR(INDEX('Resource Master'!$A$2:$A$19,MATCH(0,COUNTIF($AB$3:AB7,'Resource Master'!$A$2:$A$19),0)),"")} -> Infrastructure Lead
B9: Max. Sites en paralelo (palanca de paralelismo) | C9: =3 -> 3 | AB9: {=IFERROR(INDEX('Resource Master'!$A$2:$A$19,MATCH(0,COUNTIF($AB$3:AB8,'Resource Master'!$A$2:$A$19),0)),"")} -> Functional Lead
B10: Fuente de recursos disponibles (Resource Master) | C10: ="Actual" -> Actual | AB10: {=IFERROR(INDEX('Resource Master'!$A$2:$A$19,MATCH(0,COUNTIF($AB$3:AB9,'Resource Master'!$A$2:$A$19),0)),"")} -> SAP Integrations Lead
B11: Metodo de etiquetado (fuente: Financials (USD)) | C11: ="Label Printers / Labelers" -> Label Printers / Labelers | AB11: {=IFERROR(INDEX('Resource Master'!$A$2:$A$19,MATCH(0,COUNTIF($AB$3:AB10,'Resource Master'!$A$2:$A$19),0)),"")} -> SAP Integrations Specialist
B12: Estrategia de WiFi (fuente: Financials (USD)) | C12: ="WiFi Full" -> WiFi Full | AB12: {=IFERROR(INDEX('Resource Master'!$A$2:$A$19,MATCH(0,COUNTIF($AB$3:AB11,'Resource Master'!$A$2:$A$19),0)),"")} -> Azure Lead
B13: Objetivo de duracion del programa (meses, fuente: ENTREGABLES) | C13: =8 -> 8 | AB13: {=IFERROR(INDEX('Resource Master'!$A$2:$A$19,MATCH(0,COUNTIF($AB$3:AB12,'Resource Master'!$A$2:$A$19),0)),"")} -> Azure Specialist
AB14: {=IFERROR(INDEX('Resource Master'!$A$2:$A$19,MATCH(0,COUNTIF($AB$3:AB13,'Resource Master'!$A$2:$A$19),0)),"")} -> Testing Lead
B15: RECURSOS DISPONIBLES POR ROL (fuente: Resource Master) | AB15: {=IFERROR(INDEX('Resource Master'!$A$2:$A$19,MATCH(0,COUNTIF($AB$3:AB14,'Resource Master'!$A$2:$A$19),0)),"")} -> Trainers
B16: Rol | C16: Disponible (fuente seleccionada) | D16: Ajuste manual (opcional) | E16: Disponible usado en el simulador | AB16: {=IFERROR(INDEX('Resource Master'!$A$2:$A$19,MATCH(0,COUNTIF($AB$3:AB15,'Resource Master'!$A$2:$A$19),0)),"")} -> Functional Lead Vendor A
B17: ='01_INPUTS'!$AB$3 -> Solution Architect | C17: =SUMIF('Resource Master'!$A$2:$A$19,B17,INDEX('Resource Master'!$G$2:$H$19,0,MATCH($C$10,'Resource Master'!$G$1:$H$1,0))) -> 1 | E17: =IF(D17="",C17,D17) -> 1 | AB17: {=IFERROR(INDEX('Resource Master'!$A$2:$A$19,MATCH(0,COUNTIF($AB$3:AB16,'Resource Master'!$A$2:$A$19),0)),"")} -> Support Lead
B18: ='01_INPUTS'!$AB$4 -> Warehouse Manager Org A | C18: =SUMIF('Resource Master'!$A$2:$A$19,B18,INDEX('Resource Master'!$G$2:$H$19,0,MATCH($C$10,'Resource Master'!$G$1:$H$1,0))) -> 1 | E18: =IF(D18="",C18,D18) -> 1
B19: ='01_INPUTS'!$AB$5 -> Project Manager Country B | C19: =SUMIF('Resource Master'!$A$2:$A$19,B19,INDEX('Resource Master'!$G$2:$H$19,0,MATCH($C$10,'Resource Master'!$G$1:$H$1,0))) -> 1 | E19: =IF(D19="",C19,D19) -> 1
B20: ='01_INPUTS'!$AB$6 -> Project Manager Country A | C20: =SUMIF('Resource Master'!$A$2:$A$19,B20,INDEX('Resource Master'!$G$2:$H$19,0,MATCH($C$10,'Resource Master'!$G$1:$H$1,0))) -> 1 | E20: =IF(D20="",C20,D20) -> 1
B21: ='01_INPUTS'!$AB$7 -> Change Management Lead | C21: =SUMIF('Resource Master'!$A$2:$A$19,B21,INDEX('Resource Master'!$G$2:$H$19,0,MATCH($C$10,'Resource Master'!$G$1:$H$1,0))) -> 2 | E21: =IF(D21="",C21,D21) -> 2
B22: ='01_INPUTS'!$AB$8 -> Infrastructure Lead | C22: =SUMIF('Resource Master'!$A$2:$A$19,B22,INDEX('Resource Master'!$G$2:$H$19,0,MATCH($C$10,'Resource Master'!$G$1:$H$1,0))) -> 2 | E22: =IF(D22="",C22,D22) -> 2
B23: ='01_INPUTS'!$AB$9 -> Functional Lead | C23: =SUMIF('Resource Master'!$A$2:$A$19,B23,INDEX('Resource Master'!$G$2:$H$19,0,MATCH($C$10,'Resource Master'!$G$1:$H$1,0))) -> 2 | E23: =IF(D23="",C23,D23) -> 2
B24: ='01_INPUTS'!$AB$10 -> SAP Integrations Lead | C24: =SUMIF('Resource Master'!$A$2:$A$19,B24,INDEX('Resource Master'!$G$2:$H$19,0,MATCH($C$10,'Resource Master'!$G$1:$H$1,0))) -> 1 | E24: =IF(D24="",C24,D24) -> 1
B25: ='01_INPUTS'!$AB$11 -> SAP Integrations Specialist | C25: =SUMIF('Resource Master'!$A$2:$A$19,B25,INDEX('Resource Master'!$G$2:$H$19,0,MATCH($C$10,'Resource Master'!$G$1:$H$1,0))) -> 1 | E25: =IF(D25="",C25,D25) -> 1
B26: ='01_INPUTS'!$AB$12 -> Azure Lead | C26: =SUMIF('Resource Master'!$A$2:$A$19,B26,INDEX('Resource Master'!$G$2:$H$19,0,MATCH($C$10,'Resource Master'!$G$1:$H$1,0))) -> 1 | E26: =IF(D26="",C26,D26) -> 1
B27: ='01_INPUTS'!$AB$13 -> Azure Specialist | C27: =SUMIF('Resource Master'!$A$2:$A$19,B27,INDEX('Resource Master'!$G$2:$H$19,0,MATCH($C$10,'Resource Master'!$G$1:$H$1,0))) -> 1 | E27: =IF(D27="",C27,D27) -> 1
B28: ='01_INPUTS'!$AB$14 -> Testing Lead | C28: =SUMIF('Resource Master'!$A$2:$A$19,B28,INDEX('Resource Master'!$G$2:$H$19,0,MATCH($C$10,'Resource Master'!$G$1:$H$1,0))) -> 1 | E28: =IF(D28="",C28,D28) -> 1
B29: ='01_INPUTS'!$AB$15 -> Trainers | C29: =SUMIF('Resource Master'!$A$2:$A$19,B29,INDEX('Resource Master'!$G$2:$H$19,0,MATCH($C$10,'Resource Master'!$G$1:$H$1,0))) -> 1 | E29: =IF(D29="",C29,D29) -> 1
B30: ='01_INPUTS'!$AB$16 -> Functional Lead Vendor A | C30: =SUMIF('Resource Master'!$A$2:$A$19,B30,INDEX('Resource Master'!$G$2:$H$19,0,MATCH($C$10,'Resource Master'!$G$1:$H$1,0))) -> 2 | E30: =IF(D30="",C30,D30) -> 2
B31: ='01_INPUTS'!$AB$17 -> Support Lead | C31: =SUMIF('Resource Master'!$A$2:$A$19,B31,INDEX('Resource Master'!$G$2:$H$19,0,MATCH($C$10,'Resource Master'!$G$1:$H$1,0))) -> 2 | E31: =IF(D31="",C31,D31) -> 2
B33: SECUENCIA / PRIORIDAD DE SITES (fuente: Sites Master)
B34: Site | C34: Pais | D34: Cluster | E34: Prioridad (1=primero, editable)
B35: ='Sites Master'!$B$2 -> Site 01 | C35: ='Sites Master'!$A$2 -> Mexico | D35: ='Sites Master'!$C$2 -> 2 | E35: =1 -> 1
B36: ='Sites Master'!$B$3 -> Site 02 | C36: ='Sites Master'!$A$3 -> Mexico | D36: ='Sites Master'!$C$3 -> 2 | E36: =2 -> 2
B37: ='Sites Master'!$B$4 -> Site 03 | C37: ='Sites Master'!$A$4 -> Mexico | D37: ='Sites Master'!$C$4 -> 2 | E37: =3 -> 3
B38: ='Sites Master'!$B$5 -> Site 04 | C38: ='Sites Master'!$A$5 -> Mexico | D38: ='Sites Master'!$C$5 -> 2 | E38: =4 -> 4
B39: ='Sites Master'!$B$6 -> Site 05 | C39: ='Sites Master'!$A$6 -> Mexico | D39: ='Sites Master'!$C$6 -> 3 | E39: =5 -> 5
B40: ='Sites Master'!$B$7 -> Site 06 | C40: ='Sites Master'!$A$7 -> Mexico | D40: ='Sites Master'!$C$7 -> 1 | E40: =6 -> 6
B41: ='Sites Master'!$B$8 -> Site 07 | C41: ='Sites Master'!$A$8 -> Mexico | D41: ='Sites Master'!$C$8 -> 2 | E41: =7 -> 7
...

Sheet 02_SCHEDULE
B2: SIMULADOR WMS - 02_SCHEDULE (cronograma por Site y Fase)
B3: Duracion total (semanas): | C3: =MAX($L$5:$L$124) -> 86 | D3: Duracion total (meses): | E3: =C3/4.345 -> 19.792865 | F3: Fecha fin programa: | G3: =MAX($J$5:$J$124) -> 46852 | H3: Objetivo (meses): | I3: ='01_INPUTS'!$C$13 -> 8 | J3: Cumple objetivo? | K3: =IF(E3<=I3,"CUMPLE","NO CUMPLE") -> NO CUMPLE | O3: ZONA DE CALCULO: secuenciacion de sites por prioridad y paralelismo (no editar)
B4: Site | C4: Pais | D4: Cluster | E4: Deployment Maturity | F4: Fase | G4: Secuencia | H4: Duracion (semanas) | I4: Fecha Inicio | J4: Fecha Fin | K4: Semana Inicio | L4: Semana Fin | M4: Key (uso interno 03_RESOURCES) | O4: Prioridad | P4: Site | Q4: Cluster | R4: Duracion total site (sem) | S4: Inicio Site | T4: Fin Site
B5: ='Sites Master'!$B$2 -> Site 01 | C5: ='Sites Master'!$A$2 -> Mexico | D5: ='Sites Master'!$C$2 -> 2 | E5: ='01_INPUTS'!$C$8 -> A | F5: {=INDEX('Implementation Phases'!$B$2:$B$9,G5)} -> Site Readiness | G5: =1 -> 1 | H5: {=IFERROR(_xlfn.XLOOKUP(1,('Implementation Phases'!$A$2:$A$65=D5)*('Implementation Phases'!$D$2:$D$65=E5)*('Implementation Phases'!$C$2:$C$65=G5),'Implementation Phases'!$E$2:$E$65),0)} -> 4 | I5: =INDEX($S$5:$S$19,MATCH(B5,$P$5:$P$19,0)) -> 46251 | J5: =IF(H5=0,I5,I5+H5*7-1) -> 46278 | K5: =ROUNDUP((I5-'01_INPUTS'!$C$7+1)/7,0) -> 1 | L5: =ROUNDUP((J5-'01_INPUTS'!$C$7+1)/7,0) -> 4 | M5: =B5&"|"&F5 -> Site 01|Site Readiness | O5: =5-4 -> 1 | P5: =INDEX('01_INPUTS'!$B$35:$B$49,MATCH(O5,'01_INPUTS'!$E$35:$E$49,0)) -> Site 01 | Q5: =INDEX('01_INPUTS'!$D$35:$D$49,MATCH(O5,'01_INPUTS'!$E$35:$E$49,0)) -> 2 | R5: =SUMIFS('Implementation Phases'!$E$2:$E$65,'Implementation Phases'!$A$2:$A$65,Q5,'Implementation Phases'!$D$2:$D$65,'01_INPUTS'!$C$8) -> 16 | S5: =IFERROR(IF(O5<='01_INPUTS'!$C$9,'01_INPUTS'!$C$7,INDEX($T$5:$T$19,MATCH(O5-'01_INPUTS'!$C$9,$O$5:$O$19,0))+1),'01_INPUTS'!$C$7) -> 46251 | T5: =S5+R5*7-1 -> 46362
B6: ='Sites Master'!$B$2 -> Site 01 | C6: ='Sites Master'!$A$2 -> Mexico | D6: ='Sites Master'!$C$2 -> 2 | E6: ='01_INPUTS'!$C$8 -> A | F6: {=INDEX('Implementation Phases'!$B$2:$B$9,G6)} -> Design Adaptation | G6: =2 -> 2 | H6: {=IFERROR(_xlfn.XLOOKUP(1,('Implementation Phases'!$A$2:$A$65=D6)*('Implementation Phases'!$D$2:$D$65=E6)*('Implementation Phases'!$C$2:$C$65=G6),'Implementation Phases'!$E$2:$E$65),0)} -> 1 | I6: =J5+1 -> 46279 | J6: =IF(H6=0,I6,I6+H6*7-1) -> 46285 | K6: =ROUNDUP((I6-'01_INPUTS'!$C$7+1)/7,0) -> 5 | L6: =ROUNDUP((J6-'01_INPUTS'!$C$7+1)/7,0) -> 5 | M6: =B6&"|"&F6 -> Site 01|Design Adaptation | O6: =6-4 -> 2 | P6: =INDEX('01_INPUTS'!$B$35:$B$49,MATCH(O6,'01_INPUTS'!$E$35:$E$49,0)) -> Site 02 | Q6: =INDEX('01_INPUTS'!$D$35:$D$49,MATCH(O6,'01_INPUTS'!$E$35:$E$49,0)) -> 2 | R6: =SUMIFS('Implementation Phases'!$E$2:$E$65,'Implementation Phases'!$A$2:$A$65,Q6,'Implementation Phases'!$D$2:$D$65,'01_INPUTS'!$C$8) -> 16 | S6: =IFERROR(IF(O6<='01_INPUTS'!$C$9,'01_INPUTS'!$C$7,INDEX($T$5:$T$19,MATCH(O6-'01_INPUTS'!$C$9,$O$5:$O$19,0))+1),'01_INPUTS'!$C$7) -> 46251 | T6: =S6+R6*7-1 -> 46362
B7: ='Sites Master'!$B$2 -> Site 01 | C7: ='Sites Master'!$A$2 -> Mexico | D7: ='Sites Master'!$C$2 -> 2 | E7: ='01_INPUTS'!$C$8 -> A | F7: {=INDEX('Implementation Phases'!$B$2:$B$9,G7)} -> Functional Review | G7: =3 -> 3 | H7: {=IFERROR(_xlfn.XLOOKUP(1,('Implementation Phases'!$A$2:$A$65=D7)*('Implementation Phases'!$D$2:$D$65=E7)*('Implementation Phases'!$C$2:$C$65=G7),'Implementation Phases'!$E$2:$E$65),0)} -> 1 | I7: =J6+1 -> 46286 | J7: =IF(H7=0,I7,I7+H7*7-1) -> 46292 | K7: =ROUNDUP((I7-'01_INPUTS'!$C$7+1)/7,0) -> 6 | L7: =ROUNDUP((J7-'01_INPUTS'!$C$7+1)/7,0) -> 6 | M7: =B7&"|"&F7 -> Site 01|Functional Review | O7: =7-4 -> 3 | P7: =INDEX('01_INPUTS'!$B$35:$B$49,MATCH(O7,'01_INPUTS'!$E$35:$E$49,0)) -> Site 03 | Q7: =INDEX('01_INPUTS'!$D$35:$D$49,MATCH(O7,'01_INPUTS'!$E$35:$E$49,0)) -> 2 | R7: =SUMIFS('Implementation Phases'!$E$2:$E$65,'Implementation Phases'!$A$2:$A$65,Q7,'Implementation Phases'!$D$2:$D$65,'01_INPUTS'!$C$8) -> 16 | S7: =IFERROR(IF(O7<='01_INPUTS'!$C$9,'01_INPUTS'!$C$7,INDEX($T$5:$T$19,MATCH(O7-'01_INPUTS'!$C$9,$O$5:$O$19,0))+1),'01_INPUTS'!$C$7) -> 46251 | T7: =S7+R7*7-1 -> 46362
B8: ='Sites Master'!$B$2 -> Site 01 | C8: ='Sites Master'!$A$2 -> Mexico | D8: ='Sites Master'!$C$2 -> 2 | E8: ='01_INPUTS'!$C$8 -> A | F8: {=INDEX('Implementation Phases'!$B$2:$B$9,G8)} -> UAT | G8: =4 -> 4 | H8: {=IFERROR(_xlfn.XLOOKUP(1,('Implementation Phases'!$A$2:$A$65=D8)*('Implementation Phases'!$D$2:$D$65=E8)*('Implementation Phases'!$C$2:$C$65=G8),'Implementation Phases'!$E$2:$E$65),0)} -> 2 | I8: =J7+1 -> 46293 | J8: =IF(H8=0,I8,I8+H8*7-1) -> 46306 | K8: =ROUNDUP((I8-'01_INPUTS'!$C$7+1)/7,0) -> 7 | L8: =ROUNDUP((J8-'01_INPUTS'!$C$7+1)/7,0) -> 8 | M8: =B8&"|"&F8 -> Site 01|UAT | O8: =8-4 -> 4 | P8: =INDEX('01_INPUTS'!$B$35:$B$49,MATCH(O8,'01_INPUTS'!$E$35:$E$49,0)) -> Site 04 | Q8: =INDEX('01_INPUTS'!$D$35:$D$49,MATCH(O8,'01_INPUTS'!$E$35:$E$49,0)) -> 2 | R8: =SUMIFS('Implementation Phases'!$E$2:$E$65,'Implementation Phases'!$A$2:$A$65,Q8,'Implementation Phases'!$D$2:$D$65,'01_INPUTS'!$C$8) -> 16 | S8: =IFERROR(IF(O8<='01_INPUTS'!$C$9,'01_INPUTS'!$C$7,INDEX($T$5:$T$19,MATCH(O8-'01_INPUTS'!$C$9,$O$5:$O$19,0))+1),'01_INPUTS'!$C$7) -> 46363 | T8: =S8+R8*7-1 -> 46474
B9: ='Sites Master'!$B$2 -> Site 01 | C9: ='Sites Master'!$A$2 -> Mexico | D9: ='Sites Master'!$C$2 -> 2 | E9: ='01_INPUTS'!$C$8 -> A | F9: {=INDEX('Implementation Phases'!$B$2:$B$9,G9)} -> Training | G9: =5 -> 5 | H9: {=IFERROR(_xlfn.XLOOKUP(1,('Implementation Phases'!$A$2:$A$65=D9)*('Implementation Phases'!$D$2:$D$65=E9)*('Implementation Phases'!$C$2:$C$65=G9),'Implementation Phases'!$E$2:$E$65),0)} -> 2 | I9: =J8+1 -> 46307 | J9: =IF(H9=0,I9,I9+H9*7-1) -> 46320 | K9: =ROUNDUP((I9-'01_INPUTS'!$C$7+1)/7,0) -> 9 | L9: =ROUNDUP((J9-'01_INPUTS'!$C$7+1)/7,0) -> 10 | M9: =B9&"|"&F9 -> Site 01|Training | O9: =9-4 -> 5 | P9: =INDEX('01_INPUTS'!$B$35:$B$49,MATCH(O9,'01_INPUTS'!$E$35:$E$49,0)) -> Site 05 | Q9: =INDEX('01_INPUTS'!$D$35:$D$49,MATCH(O9,'01_INPUTS'!$E$35:$E$49,0)) -> 3 | R9: =SUMIFS('Implementation Phases'!$E$2:$E$65,'Implementation Phases'!$A$2:$A$65,Q9,'Implementation Phases'!$D$2:$D$65,'01_INPUTS'!$C$8) -> 15 | S9: =IFERROR(IF(O9<='01_INPUTS'!$C$9,'01_INPUTS'!$C$7,INDEX($T$5:$T$19,MATCH(O9-'01_INPUTS'!$C$9,$O$5:$O$19,0))+1),'01_INPUTS'!$C$7) -> 46363 | T9: =S9+R9*7-1 -> 46467
B10: ='Sites Master'!$B$2 -> Site 01 | C10: ='Sites Master'!$A$2 -> Mexico | D10: ='Sites Master'!$C$2 -> 2 | E10: ='01_INPUTS'!$C$8 -> A | F10: {=INDEX('Implementation Phases'!$B$2:$B$9,G10)} -> DIALT | G10: =6 -> 6 | H10: {=IFERROR(_xlfn.XLOOKUP(1,('Implementation Phases'!$A$2:$A$65=D10)*('Implementation Phases'!$D$2:$D$65=E10)*('Implementation Phases'!$C$2:$C$65=G10),'Implementation Phases'!$E$2:$E$65),0)} -> 1 | I10: =J9+1 -> 46321 | J10: =IF(H10=0,I10,I10+H10*7-1) -> 46327 | K10: =ROUNDUP((I10-'01_INPUTS'!$C$7+1)/7,0) -> 11 | L10: =ROUNDUP((J10-'01_INPUTS'!$C$7+1)/7,0) -> 11 | M10: =B10&"|"&F10 -> Site 01|DIALT | O10: =10-4 -> 6 | P10: =INDEX('01_INPUTS'!$B$35:$B$49,MATCH(O10,'01_INPUTS'!$E$35:$E$49,0)) -> Site 06 | Q10: =INDEX('01_INPUTS'!$D$35:$D$49,MATCH(O10,'01_INPUTS'!$E$35:$E$49,0)) -> 1 | R10: =SUMIFS('Implementation Phases'!$E$2:$E$65,'Implementation Phases'!$A$2:$A$65,Q10,'Implementation Phases'!$D$2:$D$65,'01_INPUTS'!$C$8) -> 19 | S10: =IFERROR(IF(O10<='01_INPUTS'!$C$9,'01_INPUTS'!$C$7,INDEX($T$5:$T$19,MATCH(O10-'01_INPUTS'!$C$9,$O$5:$O$19,0))+1),'01_INPUTS'!$C$7) -> 46363 | T10: =S10+R10*7-1 -> 46495
B11: ='Sites Master'!$B$2 -> Site 01 | C11: ='Sites Master'!$A$2 -> Mexico | D11: ='Sites Master'!$C$2 -> 2 | E11: ='01_INPUTS'!$C$8 -> A | F11: {=INDEX('Implementation Phases'!$B$2:$B$9,G11)} -> Go Live | G11: =7 -> 7 | H11: {=IFERROR(_xlfn.XLOOKUP(1,('Implementation Phases'!$A$2:$A$65=D11)*('Implementation Phases'!$D$2:$D$65=E11)*('Implementation Phases'!$C$2:$C$65=G11),'Implementation Phases'!$E$2:$E$65),0)} -> 1 | I11: =J10+1 -> 46328 | J11: =IF(H11=0,I11,I11+H11*7-1) -> 46334 | K11: =ROUNDUP((I11-'01_INPUTS'!$C$7+1)/7,0) -> 12 | L11: =ROUNDUP((J11-'01_INPUTS'!$C$7+1)/7,0) -> 12 | M11: =B11&"|"&F11 -> Site 01|Go Live | O11: =11-4 -> 7 | P11: =INDEX('01_INPUTS'!$B$35:$B$49,MATCH(O11,'01_INPUTS'!$E$35:$E$49,0)) -> Site 07 | Q11: =INDEX('01_INPUTS'!$D$35:$D$49,MATCH(O11,'01_INPUTS'!$E$35:$E$49,0)) -> 2 | R11: =SUMIFS('Implementation Phases'!$E$2:$E$65,'Implementation Phases'!$A$2:$A$65,Q11,'Implementation Phases'!$D$2:$D$65,'01_INPUTS'!$C$8) -> 16 | S11: =IFERROR(IF(O11<='01_INPUTS'!$C$9,'01_INPUTS'!$C$7,INDEX($T$5:$T$19,MATCH(O11-'01_INPUTS'!$C$9,$O$5:$O$19,0))+1),'01_INPUTS'!$C$7) -> 46475 | T11: =S11+R11*7-1 -> 46586
B12: ='Sites Master'!$B$2 -> Site 01 | C12: ='Sites Master'!$A$2 -> Mexico | D12: ='Sites Master'!$C$2 -> 2 | E12: ='01_INPUTS'!$C$8 -> A | F12: {=INDEX('Implementation Phases'!$B$2:$B$9,G12)} -> Hypercare | G12: =8 -> 8 | H12: {=IFERROR(_xlfn.XLOOKUP(1,('Implementation Phases'!$A$2:$A$65=D12)*('Implementation Phases'!$D$2:$D$65=E12)*('Implementation Phases'!$C$2:$C$65=G12),'Implementation Phases'!$E$2:$E$65),0)} -> 4 | I12: =J11+1 -> 46335 | J12: =IF(H12=0,I12,I12+H12*7-1) -> 46362 | K12: =ROUNDUP((I12-'01_INPUTS'!$C$7+1)/7,0) -> 13 | L12: =ROUNDUP((J12-'01_INPUTS'!$C$7+1)/7,0) -> 16 | M12: =B12&"|"&F12 -> Site 01|Hypercare | O12: =12-4 -> 8 | P12: =INDEX('01_INPUTS'!$B$35:$B$49,MATCH(O12,'01_INPUTS'!$E$35:$E$49,0)) -> Site 08 | Q12: =INDEX('01_INPUTS'!$D$35:$D$49,MATCH(O12,'01_INPUTS'!$E$35:$E$49,0)) -> 1 | R12: =SUMIFS('Implementation Phases'!$E$2:$E$65,'Implementation Phases'!$A$2:$A$65,Q12,'Implementation Phases'!$D$2:$D$65,'01_INPUTS'!$C$8) -> 19 | S12: =IFERROR(IF(O12<='01_INPUTS'!$C$9,'01_INPUTS'!$C$7,INDEX($T$5:$T$19,MATCH(O12-'01_INPUTS'!$C$9,$O$5:$O$19,0))+1),'01_INPUTS'!$C$7) -> 46468 | T12: =S12+R12*7-1 -> 46600
B13: ='Sites Master'!$B$3 -> Site 02 | C13: ='Sites Master'!$A$3 -> Mexico | D13: ='Sites Master'!$C$3 -> 2 | E13: ='01_INPUTS'!$C$8 -> A | F13: {=INDEX('Implementation Phases'!$B$2:$B$9,G13)} -> Site Readiness | G13: =1 -> 1 | H13: {=IFERROR(_xlfn.XLOOKUP(1,('Implementation Phases'!$A$2:$A$65=D13)*('Implementation Phases'!$D$2:$D$65=E13)*('Implementation Phases'!$C$2:$C$65=G13),'Implementation Phases'!$E$2:$E$65),0)} -> 4 | I13: =INDEX($S$5:$S$19,MATCH(B13,$P$5:$P$19,0)) -> 46251 | J13: =IF(H13=0,I13,I13+H13*7-1) -> 46278 | K13: =ROUNDUP((I13-'01_INPUTS'!$C$7+1)/7,0) -> 1 | L13: =ROUNDUP((J13-'01_INPUTS'!$C$7+1)/7,0) -> 4 | M13: =B13&"|"&F13 -> Site 02|Site Readiness | O13: =13-4 -> 9 | P13: =INDEX('01_INPUTS'!$B$35:$B$49,MATCH(O13,'01_INPUTS'!$E$35:$E$49,0)) -> Site 09 | Q13: =INDEX('01_INPUTS'!$D$35:$D$49,MATCH(O13,'01_INPUTS'!$E$35:$E$49,0)) -> 2 | R13: =SUMIFS('Implementation Phases'!$E$2:$E$65,'Implementation Phases'!$A$2:$A$65,Q13,'Implementation Phases'!$D$2:$D$65,'01_INPUTS'!$C$8) -> 16 | S13: =IFERROR(IF(O13<='01_INPUTS'!$C$9,'01_INPUTS'!$C$7,INDEX($T$5:$T$19,MATCH(O13-'01_INPUTS'!$C$9,$O$5:$O$19,0))+1),'01_INPUTS'!$C$7) -> 46496 | T13: =S13+R13*7-1 -> 46607
B14: ='Sites Master'!$B$3 -> Site 02 | C14: ='Sites Master'!$A$3 -> Mexico | D14: ='Sites Master'!$C$3 -> 2 | E14: ='01_INPUTS'!$C$8 -> A | F14: {=INDEX('Implementation Phases'!$B$2:$B$9,G14)} -> Design Adaptation | G14: =2 -> 2 | H14: {=IFERROR(_xlfn.XLOOKUP(1,('Implementation Phases'!$A$2:$A$65=D14)*('Implementation Phases'!$D$2:$D$65=E14)*('Implementation Phases'!$C$2:$C$65=G14),'Implementation Phases'!$E$2:$E$65),0)} -> 1 | I14: =J13+1 -> 46279 | J14: =IF(H14=0,I14,I14+H14*7-1) -> 46285 | K14: =ROUNDUP((I14-'01_INPUTS'!$C$7+1)/7,0) -> 5 | L14: =ROUNDUP((J14-'01_INPUTS'!$C$7+1)/7,0) -> 5 | M14: =B14&"|"&F14 -> Site 02|Design Adaptation | O14: =14-4 -> 10 | P14: =INDEX('01_INPUTS'!$B$35:$B$49,MATCH(O14,'01_INPUTS'!$E$35:$E$49,0)) -> Site 10 | Q14: =INDEX('01_INPUTS'!$D$35:$D$49,MATCH(O14,'01_INPUTS'!$E$35:$E$49,0)) -> 1 | R14: =SUMIFS('Implementation Phases'!$E$2:$E$65,'Implementation Phases'!$A$2:$A$65,Q14,'Implementation Phases'!$D$2:$D$65,'01_INPUTS'!$C$8) -> 19 | S14: =IFERROR(IF(O14<='01_INPUTS'!$C$9,'01_INPUTS'!$C$7,INDEX($T$5:$T$19,MATCH(O14-'01_INPUTS'!$C$9,$O$5:$O$19,0))+1),'01_INPUTS'!$C$7) -> 46587 | T14: =S14+R14*7-1 -> 46719
B15: ='Sites Master'!$B$3 -> Site 02 | C15: ='Sites Master'!$A$3 -> Mexico | D15: ='Sites Master'!$C$3 -> 2 | E15: ='01_INPUTS'!$C$8 -> A | F15: {=INDEX('Implementation Phases'!$B$2:$B$9,G15)} -> Functional Review | G15: =3 -> 3 | H15: {=IFERROR(_xlfn.XLOOKUP(1,('Implementation Phases'!$A$2:$A$65=D15)*('Implementation Phases'!$D$2:$D$65=E15)*('Implementation Phases'!$C$2:$C$65=G15),'Implementation Phases'!$E$2:$E$65),0)} -> 1 | I15: =J14+1 -> 46286 | J15: =IF(H15=0,I15,I15+H15*7-1) -> 46292 | K15: =ROUNDUP((I15-'01_INPUTS'!$C$7+1)/7,0) -> 6 | L15: =ROUNDUP((J15-'01_INPUTS'!$C$7+1)/7,0) -> 6 | M15: =B15&"|"&F15 -> Site 02|Functional Review | O15: =15-4 -> 11 | P15: =INDEX('01_INPUTS'!$B$35:$B$49,MATCH(O15,'01_INPUTS'!$E$35:$E$49,0)) -> Site 11 | Q15: =INDEX('01_INPUTS'!$D$35:$D$49,MATCH(O15,'01_INPUTS'!$E$35:$E$49,0)) -> 3 | R15: =SUMIFS('Implementation Phases'!$E$2:$E$65,'Implementation Phases'!$A$2:$A$65,Q15,'Implementation Phases'!$D$2:$D$65,'01_INPUTS'!$C$8) -> 15 | S15: =IFERROR(IF(O15<='01_INPUTS'!$C$9,'01_INPUTS'!$C$7,INDEX($T$5:$T$19,MATCH(O15-'01_INPUTS'!$C$9,$O$5:$O$19,0))+1),'01_INPUTS'!$C$7) -> 46601 | T15: =S15+R15*7-1 -> 46705
B16: ='Sites Master'!$B$3 -> Site 02 | C16: ='Sites Master'!$A$3 -> Mexico | D16: ='Sites Master'!$C$3 -> 2 | E16: ='01_INPUTS'!$C$8 -> A | F16: {=INDEX('Implementation Phases'!$B$2:$B$9,G16)} -> UAT | G16: =4 -> 4 | H16: {=IFERROR(_xlfn.XLOOKUP(1,('Implementation Phases'!$A$2:$A$65=D16)*('Implementation Phases'!$D$2:$D$65=E16)*('Implementation Phases'!$C$2:$C$65=G16),'Implementation Phases'!$E$2:$E$65),0)} -> 2 | I16: =J15+1 -> 46293 | J16: =IF(H16=0,I16,I16+H16*7-1) -> 46306 | K16: =ROUNDUP((I16-'01_INPUTS'!$C$7+1)/7,0) -> 7 | L16: =ROUNDUP((J16-'01_INPUTS'!$C$7+1)/7,0) -> 8 | M16: =B16&"|"&F16 -> Site 02|UAT | O16: =16-4 -> 12 | P16: =INDEX('01_INPUTS'!$B$35:$B$49,MATCH(O16,'01_INPUTS'!$E$35:$E$49,0)) -> Site 12 | Q16: =INDEX('01_INPUTS'!$D$35:$D$49,MATCH(O16,'01_INPUTS'!$E$35:$E$49,0)) -> 4 | R16: =SUMIFS('Implementation Phases'!$E$2:$E$65,'Implementation Phases'!$A$2:$A$65,Q16,'Implementation Phases'!$D$2:$D$65,'01_INPUTS'!$C$8) -> 10 | S16: =IFERROR(IF(O16<='01_INPUTS'!$C$9,'01_INPUTS'!$C$7,INDEX($T$5:$T$19,MATCH(O16-'01_INPUTS'!$C$9,$O$5:$O$19,0))+1),'01_INPUTS'!$C$7) -> 46608 | T16: =S16+R16*7-1 -> 46677
B17: ='Sites Master'!$B$3 -> Site 02 | C17: ='Sites Master'!$A$3 -> Mexico | D17: ='Sites Master'!$C$3 -> 2 | E17: ='01_INPUTS'!$C$8 -> A | F17: {=INDEX('Implementation Phases'!$B$2:$B$9,G17)} -> Training | G17: =5 -> 5 | H17: {=IFERROR(_xlfn.XLOOKUP(1,('Implementation Phases'!$A$2:$A$65=D17)*('Implementation Phases'!$D$2:$D$65=E17)*('Implementation Phases'!$C$2:$C$65=G17),'Implementation Phases'!$E$2:$E$65),0)} -> 2 | I17: =J16+1 -> 46307 | J17: =IF(H17=0,I17,I17+H17*7-1) -> 46320 | K17: =ROUNDUP((I17-'01_INPUTS'!$C$7+1)/7,0) -> 9 | L17: =ROUNDUP((J17-'01_INPUTS'!$C$7+1)/7,0) -> 10 | M17: =B17&"|"&F17 -> Site 02|Training | O17: =17-4 -> 13 | P17: =INDEX('01_INPUTS'!$B$35:$B$49,MATCH(O17,'01_INPUTS'!$E$35:$E$49,0)) -> Site 13 | Q17: =INDEX('01_INPUTS'!$D$35:$D$49,MATCH(O17,'01_INPUTS'!$E$35:$E$49,0)) -> 1 | R17: =SUMIFS('Implementation Phases'!$E$2:$E$65,'Implementation Phases'!$A$2:$A$65,Q17,'Implementation Phases'!$D$2:$D$65,'01_INPUTS'!$C$8) -> 19 | S17: =IFERROR(IF(O17<='01_INPUTS'!$C$9,'01_INPUTS'!$C$7,INDEX($T$5:$T$19,MATCH(O17-'01_INPUTS'!$C$9,$O$5:$O$19,0))+1),'01_INPUTS'!$C$7) -> 46720 | T17: =S17+R17*7-1 -> 46852
B18: ='Sites Master'!$B$3 -> Site 02 | C18: ='Sites Master'!$A$3 -> Mexico | D18: ='Sites Master'!$C$3 -> 2 | E18: ='01_INPUTS'!$C$8 -> A | F18: {=INDEX('Implementation Phases'!$B$2:$B$9,G18)} -> DIALT | G18: =6 -> 6 | H18: {=IFERROR(_xlfn.XLOOKUP(1,('Implementation Phases'!$A$2:$A$65=D18)*('Implementation Phases'!$D$2:$D$65=E18)*('Implementation Phases'!$C$2:$C$65=G18),'Implementation Phases'!$E$2:$E$65),0)} -> 1 | I18: =J17+1 -> 46321 | J18: =IF(H18=0,I18,I18+H18*7-1) -> 46327 | K18: =ROUNDUP((I18-'01_INPUTS'!$C$7+1)/7,0) -> 11 | L18: =ROUNDUP((J18-'01_INPUTS'!$C$7+1)/7,0) -> 11 | M18: =B18&"|"&F18 -> Site 02|DIALT | O18: =18-4 -> 14 | P18: =INDEX('01_INPUTS'!$B$35:$B$49,MATCH(O18,'01_INPUTS'!$E$35:$E$49,0)) -> Site 14 | Q18: =INDEX('01_INPUTS'!$D$35:$D$49,MATCH(O18,'01_INPUTS'!$E$35:$E$49,0)) -> 1 | R18: =SUMIFS('Implementation Phases'!$E$2:$E$65,'Implementation Phases'!$A$2:$A$65,Q18,'Implementation Phases'!$D$2:$D$65,'01_INPUTS'!$C$8) -> 19 | S18: =IFERROR(IF(O18<='01_INPUTS'!$C$9,'01_INPUTS'!$C$7,INDEX($T$5:$T$19,MATCH(O18-'01_INPUTS'!$C$9,$O$5:$O$19,0))+1),'01_INPUTS'!$C$7) -> 46706 | T18: =S18+R18*7-1 -> 46838
B19: ='Sites Master'!$B$3 -> Site 02 | C19: ='Sites Master'!$A$3 -> Mexico | D19: ='Sites Master'!$C$3 -> 2 | E19: ='01_INPUTS'!$C$8 -> A | F19: {=INDEX('Implementation Phases'!$B$2:$B$9,G19)} -> Go Live | G19: =7 -> 7 | H19: {=IFERROR(_xlfn.XLOOKUP(1,('Implementation Phases'!$A$2:$A$65=D19)*('Implementation Phases'!$D$2:$D$65=E19)*('Implementation Phases'!$C$2:$C$65=G19),'Implementation Phases'!$E$2:$E$65),0)} -> 1 | I19: =J18+1 -> 46328 | J19: =IF(H19=0,I19,I19+H19*7-1) -> 46334 | K19: =ROUNDUP((I19-'01_INPUTS'!$C$7+1)/7,0) -> 12 | L19: =ROUNDUP((J19-'01_INPUTS'!$C$7+1)/7,0) -> 12 | M19: =B19&"|"&F19 -> Site 02|Go Live | O19: =19-4 -> 15 | P19: =INDEX('01_INPUTS'!$B$35:$B$49,MATCH(O19,'01_INPUTS'!$E$35:$E$49,0)) -> Site 15 | Q19: =INDEX('01_INPUTS'!$D$35:$D$49,MATCH(O19,'01_INPUTS'!$E$35:$E$49,0)) -> 2 | R19: =SUMIFS('Implementation Phases'!$E$2:$E$65,'Implementation Phases'!$A$2:$A$65,Q19,'Implementation Phases'!$D$2:$D$65,'01_INPUTS'!$C$8) -> 16 | S19: =IFERROR(IF(O19<='01_INPUTS'!$C$9,'01_INPUTS'!$C$7,INDEX($T$5:$T$19,MATCH(O19-'01_INPUTS'!$C$9,$O$5:$O$19,0))+1),'01_INPUTS'!$C$7) -> 46678 | T19: =S19+R19*7-1 -> 46789
B20: ='Sites Master'!$B$3 -> Site 02 | C20: ='Sites Master'!$A$3 -> Mexico | D20: ='Sites Master'!$C$3 -> 2 | E20: ='01_INPUTS'!$C$8 -> A | F20: {=INDEX('Implementation Phases'!$B$2:$B$9,G20)} -> Hypercare | G20: =8 -> 8 | H20: {=IFERROR(_xlfn.XLOOKUP(1,('Implementation Phases'!$A$2:$A$65=D20)*('Implementation Phases'!$D$2:$D$65=E20)*('Implementation Phases'!$C$2:$C$65=G20),'Implementation Phases'!$E$2:$E$65),0)} -> 4 | I20: =J19+1 -> 46335 | J20: =IF(H20=0,I20,I20+H20*7-1) -> 46362 | K20: =ROUNDUP((I20-'01_INPUTS'!$C$7+1)/7,0) -> 13 | L20: =ROUNDUP((J20-'01_INPUTS'!$C$7+1)/7,0) -> 16 | M20: =B20&"|"&F20 -> Site 02|Hypercare
B21: ='Sites Master'!$B$4 -> Site 03 | C21: ='Sites Master'!$A$4 -> Mexico | D21: ='Sites Master'!$C$4 -> 2 | E21: ='01_INPUTS'!$C$8 -> A | F21: {=INDEX('Implementation Phases'!$B$2:$B$9,G21)} -> Site Readiness | G21: =1 -> 1 | H21: {=IFERROR(_xlfn.XLOOKUP(1,('Implementation Phases'!$A$2:$A$65=D21)*('Implementation Phases'!$D$2:$D$65=E21)*('Implementation Phases'!$C$2:$C$65=G21),'Implementation Phases'!$E$2:$E$65),0)} -> 4 | I21: =INDEX($S$5:$S$19,MATCH(B21,$P$5:$P$19,0)) -> 46251 | J21: =IF(H21=0,I21,I21+H21*7-1) -> 46278 | K21: =ROUNDUP((I21-'01_INPUTS'!$C$7+1)/7,0) -> 1 | L21: =ROUNDUP((J21-'01_INPUTS'!$C$7+1)/7,0) -> 4 | M21: =B21&"|"&F21 -> Site 03|Site Readiness
B22: ='Sites Master'!$B$4 -> Site 03 | C22: ='Sites Master'!$A$4 -> Mexico | D22: ='Sites Master'!$C$4 -> 2 | E22: ='01_INPUTS'!$C$8 -> A | F22: {=INDEX('Implementation Phases'!$B$2:$B$9,G22)} -> Design Adaptation | G22: =2 -> 2 | H22: {=IFERROR(_xlfn.XLOOKUP(1,('Implementation Phases'!$A$2:$A$65=D22)*('Implementation Phases'!$D$2:$D$65=E22)*('Implementation Phases'!$C$2:$C$65=G22),'Implementation Phases'!$E$2:$E$65),0)} -> 1 | I22: =J21+1 -> 46279 | J22: =IF(H22=0,I22,I22+H22*7-1) -> 46285 | K22: =ROUNDUP((I22-'01_INPUTS'!$C$7+1)/7,0) -> 5 | L22: =ROUNDUP((J22-'01_INPUTS'!$C$7+1)/7,0) -> 5 | M22: =B22&"|"&F22 -> Site 03|Design Adaptation
B23: ='Sites Master'!$B$4 -> Site 03 | C23: ='Sites Master'!$A$4 -> Mexico | D23: ='Sites Master'!$C$4 -> 2 | E23: ='01_INPUTS'!$C$8 -> A | F23: {=INDEX('Implementation Phases'!$B$2:$B$9,G23)} -> Functional Review | G23: =3 -> 3 | H23: {=IFERROR(_xlfn.XLOOKUP(1,('Implementation Phases'!$A$2:$A$65=D23)*('Implementation Phases'!$D$2:$D$65=E23)*('Implementation Phases'!$C$2:$C$65=G23),'Implementation Phases'!$E$2:$E$65),0)} -> 1 | I23: =J22+1 -> 46286 | J23: =IF(H23=0,I23,I23+H23*7-1) -> 46292 | K23: =ROUNDUP((I23-'01_INPUTS'!$C$7+1)/7,0) -> 6 | L23: =ROUNDUP((J23-'01_INPUTS'!$C$7+1)/7,0) -> 6 | M23: =B23&"|"&F23 -> Site 03|Functional Review
B24: ='Sites Master'!$B$4 -> Site 03 | C24: ='Sites Master'!$A$4 -> Mexico | D24: ='Sites Master'!$C$4 -> 2 | E24: ='01_INPUTS'!$C$8 -> A | F24: {=INDEX('Implementation Phases'!$B$2:$B$9,G24)} -> UAT | G24: =4 -> 4 | H24: {=IFERROR(_xlfn.XLOOKUP(1,('Implementation Phases'!$A$2:$A$65=D24)*('Implementation Phases'!$D$2:$D$65=E24)*('Implementation Phases'!$C$2:$C$65=G24),'Implementation Phases'!$E$2:$E$65),0)} -> 2 | I24: =J23+1 -> 46293 | J24: =IF(H24=0,I24,I24+H24*7-1) -> 46306 | K24: =ROUNDUP((I24-'01_INPUTS'!$C$7+1)/7,0) -> 7 | L24: =ROUNDUP((J24-'01_INPUTS'!$C$7+1)/7,0) -> 8 | M24: =B24&"|"&F24 -> Site 03|UAT
B25: ='Sites Master'!$B$4 -> Site 03 | C25: ='Sites Master'!$A$4 -> Mexico | D25: ='Sites Master'!$C$4 -> 2 | E25: ='01_INPUTS'!$C$8 -> A | F25: {=INDEX('Implementation Phases'!$B$2:$B$9,G25)} -> Training | G25: =5 -> 5 | H25: {=IFERROR(_xlfn.XLOOKUP(1,('Implementation Phases'!$A$2:$A$65=D25)*('Implementation Phases'!$D$2:$D$65=E25)*('Implementation Phases'!$C$2:$C$65=G25),'Implementation Phases'!$E$2:$E$65),0)} -> 2 | I25: =J24+1 -> 46307 | J25: =IF(H25=0,I25,I25+H25*7-1) -> 46320 | K25: =ROUNDUP((I25-'01_INPUTS'!$C$7+1)/7,0) -> 9 | L25: =ROUNDUP((J25-'01_INPUTS'!$C$7+1)/7,0) -> 10 | M25: =B25&"|"&F25 -> Site 03|Training
B26: ='Sites Master'!$B$4 -> Site 03 | C26: ='Sites Master'!$A$4 -> Mexico | D26: ='Sites Master'!$C$4 -> 2 | E26: ='01_INPUTS'!$C$8 -> A | F26: {=INDEX('Implementation Phases'!$B$2:$B$9,G26)} -> DIALT | G26: =6 -> 6 | H26: {=IFERROR(_xlfn.XLOOKUP(1,('Implementation Phases'!$A$2:$A$65=D26)*('Implementation Phases'!$D$2:$D$65=E26)*('Implementation Phases'!$C$2:$C$65=G26),'Implementation Phases'!$E$2:$E$65),0)} -> 1 | I26: =J25+1 -> 46321 | J26: =IF(H26=0,I26,I26+H26*7-1) -> 46327 | K26: =ROUNDUP((I26-'01_INPUTS'!$C$7+1)/7,0) -> 11 | L26: =ROUNDUP((J26-'01_INPUTS'!$C$7+1)/7,0) -> 11 | M26: =B26&"|"&F26 -> Site 03|DIALT
B27: ='Sites Master'!$B$4 -> Site 03 | C27: ='Sites Master'!$A$4 -> Mexico | D27: ='Sites Master'!$C$4 -> 2 | E27: ='01_INPUTS'!$C$8 -> A | F27: {=INDEX('Implementation Phases'!$B$2:$B$9,G27)} -> Go Live | G27: =7 -> 7 | H27: {=IFERROR(_xlfn.XLOOKUP(1,('Implementation Phases'!$A$2:$A$65=D27)*('Implementation Phases'!$D$2:$D$65=E27)*('Implementation Phases'!$C$2:$C$65=G27),'Implementation Phases'!$E$2:$E$65),0)} -> 1 | I27: =J26+1 -> 46328 | J27: =IF(H27=0,I27,I27+H27*7-1) -> 46334 | K27: =ROUNDUP((I27-'01_INPUTS'!$C$7+1)/7,0) -> 12 | L27: =ROUNDUP((J27-'01_INPUTS'!$C$7+1)/7,0) -> 12 | M27: =B27&"|"&F27 -> Site 03|Go Live
B28: ='Sites Master'!$B$4 -> Site 03 | C28: ='Sites Master'!$A$4 -> Mexico | D28: ='Sites Master'!$C$4 -> 2 | E28: ='01_INPUTS'!$C$8 -> A | F28: {=INDEX('Implementation Phases'!$B$2:$B$9,G28)} -> Hypercare | G28: =8 -> 8 | H28: {=IFERROR(_xlfn.XLOOKUP(1,('Implementation Phases'!$A$2:$A$65=D28)*('Implementation Phases'!$D$2:$D$65=E28)*('Implementation Phases'!$C$2:$C$65=G28),'Implementation Phases'!$E$2:$E$65),0)} -> 4 | I28: =J27+1 -> 46335 | J28: =IF(H28=0,I28,I28+H28*7-1) -> 46362 | K28: =ROUNDUP((I28-'01_INPUTS'!$C$7+1)/7,0) -> 13 | L28: =ROUNDUP((J28-'01_INPUTS'!$C$7+1)/7,0) -> 16 | M28: =B28&"|"&F28 -> Site 03|Hypercare
B29: ='Sites Master'!$B$5 -> Site 04 | C29: ='Sites Master'!$A$5 -> Mexico | D29: ='Sites Master'!$C$5 -> 2 | E29: ='01_INPUTS'!$C$8 -> A | F29: {=INDEX('Implementation Phases'!$B$2:$B$9,G29)} -> Site Readiness | G29: =1 -> 1 | H29: {=IFERROR(_xlfn.XLOOKUP(1,('Implementation Phases'!$A$2:$A$65=D29)*('Implementation Phases'!$D$2:$D$65=E29)*('Implementation Phases'!$C$2:$C$65=G29),'Implementation Phases'!$E$2:$E$65),0)} -> 4 | I29: =INDEX($S$5:$S$19,MATCH(B29,$P$5:$P$19,0)) -> 46363 | J29: =IF(H29=0,I29,I29+H29*7-1) -> 46390 | K29: =ROUNDUP((I29-'01_INPUTS'!$C$7+1)/7,0) -> 17 | L29: =ROUNDUP((J29-'01_INPUTS'!$C$7+1)/7,0) -> 20 | M29: =B29&"|"&F29 -> Site 04|Site Readiness
B30: ='Sites Master'!$B$5 -> Site 04 | C30: ='Sites Master'!$A$5 -> Mexico | D30: ='Sites Master'!$C$5 -> 2 | E30: ='01_INPUTS'!$C$8 -> A | F30: {=INDEX('Implementation Phases'!$B$2:$B$9,G30)} -> Design Adaptation | G30: =2 -> 2 | H30: {=IFERROR(_xlfn.XLOOKUP(1,('Implementation Phases'!$A$2:$A$65=D30)*('Implementation Phases'!$D$2:$D$65=E30)*('Implementation Phases'!$C$2:$C$65=G30),'Implementation Phases'!$E$2:$E$65),0)} -> 1 | I30: =J29+1 -> 46391 | J30: =IF(H30=0,I30,I30+H30*7-1) -> 46397 | K30: =ROUNDUP((I30-'01_INPUTS'!$C$7+1)/7,0) -> 21 | L30: =ROUNDUP((J30-'01_INPUTS'!$C$7+1)/7,0) -> 21 | M30: =B30&"|"&F30 -> Site 04|Design Adaptation
B31: ='Sites Master'!$B$5 -> Site 04 | C31: ='Sites Master'!$A$5 -> Mexico | D31: ='Sites Master'!$C$5 -> 2 | E31: ='01_INPUTS'!$C$8 -> A | F31: {=INDEX('Implementation Phases'!$B$2:$B$9,G31)} -> Functional Review | G31: =3 -> 3 | H31: {=IFERROR(_xlfn.XLOOKUP(1,('Implementation Phases'!$A$2:$A$65=D31)*('Implementation Phases'!$D$2:$D$65=E31)*('Implementation Phases'!$C$2:$C$65=G31),'Implementation Phases'!$E$2:$E$65),0)} -> 1 | I31: =J30+1 -> 46398 | J31: =IF(H31=0,I31,I31+H31*7-1) -> 46404 | K31: =ROUNDUP((I31-'01_INPUTS'!$C$7+1)/7,0) -> 22 | L31: =ROUNDUP((J31-'01_INPUTS'!$C$7+1)/7,0) -> 22 | M31: =B31&"|"&F31 -> Site 04|Functional Review
B32: ='Sites Master'!$B$5 -> Site 04 | C32: ='Sites Master'!$A$5 -> Mexico | D32: ='Sites Master'!$C$5 -> 2 | E32: ='01_INPUTS'!$C$8 -> A | F32: {=INDEX('Implementation Phases'!$B$2:$B$9,G32)} -> UAT | G32: =4 -> 4 | H32: {=IFERROR(_xlfn.XLOOKUP(1,('Implementation Phases'!$A$2:$A$65=D32)*('Implementation Phases'!$D$2:$D$65=E32)*('Implementation Phases'!$C$2:$C$65=G32),'Implementation Phases'!$E$2:$E$65),0)} -> 2 | I32: =J31+1 -> 46405 | J32: =IF(H32=0,I32,I32+H32*7-1) -> 46418 | K32: =ROUNDUP((I32-'01_INPUTS'!$C$7+1)/7,0) -> 23 | L32: =ROUNDUP((J32-'01_INPUTS'!$C$7+1)/7,0) -> 24 | M32: =B32&"|"&F32 -> Site 04|UAT
B33: ='Sites Master'!$B$5 -> Site 04 | C33: ='Sites Master'!$A$5 -> Mexico | D33: ='Sites Master'!$C$5 -> 2 | E33: ='01_INPUTS'!$C$8 -> A | F33: {=INDEX('Implementation Phases'!$B$2:$B$9,G33)} -> Training | G33: =5 -> 5 | H33: {=IFERROR(_xlfn.XLOOKUP(1,('Implementation Phases'!$A$2:$A$65=D33)*('Implementation Phases'!$D$2:$D$65=E33)*('Implementation Phases'!$C$2:$C$65=G33),'Implementation Phases'!$E$2:$E$65),0)} -> 2 | I33: =J32+1 -> 46419 | J33: =IF(H33=0,I33,I33+H33*7-1) -> 46432 | K33: =ROUNDUP((I33-'01_INPUTS'!$C$7+1)/7,0) -> 25 | L33: =ROUNDUP((J33-'01_INPUTS'!$C$7+1)/7,0) -> 26 | M33: =B33&"|"&F33 -> Site 04|Training
B34: ='Sites Master'!$B$5 -> Site 04 | C34: ='Sites Master'!$A$5 -> Mexico | D34: ='Sites Master'!$C$5 -> 2 | E34: ='01_INPUTS'!$C$8 -> A | F34: {=INDEX('Implementation Phases'!$B$2:$B$9,G34)} -> DIALT | G34: =6 -> 6 | H34: {=IFERROR(_xlfn.XLOOKUP(1,('Implementation Phases'!$A$2:$A$65=D34)*('Implementation Phases'!$D$2:$D$65=E34)*('Implementation Phases'!$C$2:$C$65=G34),'Implementation Phases'!$E$2:$E$65),0)} -> 1 | I34: =J33+1 -> 46433 | J34: =IF(H34=0,I34,I34+H34*7-1) -> 46439 | K34: =ROUNDUP((I34-'01_INPUTS'!$C$7+1)/7,0) -> 27 | L34: =ROUNDUP((J34-'01_INPUTS'!$C$7+1)/7,0) -> 27 | M34: =B34&"|"&F34 -> Site 04|DIALT
B35: ='Sites Master'!$B$5 -> Site 04 | C35: ='Sites Master'!$A$5 -> Mexico | D35: ='Sites Master'!$C$5 -> 2 | E35: ='01_INPUTS'!$C$8 -> A | F35: {=INDEX('Implementation Phases'!$B$2:$B$9,G35)} -> Go Live | G35: =7 -> 7 | H35: {=IFERROR(_xlfn.XLOOKUP(1,('Implementation Phases'!$A$2:$A$65=D35)*('Implementation Phases'!$D$2:$D$65=E35)*('Implementation Phases'!$C$2:$C$65=G35),'Implementation Phases'!$E$2:$E$65),0)} -> 1 | I35: =J34+1 -> 46440 | J35: =IF(H35=0,I35,I35+H35*7-1) -> 46446 | K35: =ROUNDUP((I35-'01_INPUTS'!$C$7+1)/7,0) -> 28 | L35: =ROUNDUP((J35-'01_INPUTS'!$C$7+1)/7,0) -> 28 | M35: =B35&"|"&F35 -> Site 04|Go Live
B36: ='Sites Master'!$B$5 -> Site 04 | C36: ='Sites Master'!$A$5 -> Mexico | D36: ='Sites Master'!$C$5 -> 2 | E36: ='01_INPUTS'!$C$8 -> A | F36: {=INDEX('Implementation Phases'!$B$2:$B$9,G36)} -> Hypercare | G36: =8 -> 8 | H36: {=IFERROR(_xlfn.XLOOKUP(1,('Implementation Phases'!$A$2:$A$65=D36)*('Implementation Phases'!$D$2:$D$65=E36)*('Implementation Phases'!$C$2:$C$65=G36),'Implementation Phases'!$E$2:$E$65),0)} -> 4 | I36: =J35+1 -> 46447 | J36: =IF(H36=0,I36,I36+H36*7-1) -> 46474 | K36: =ROUNDUP((I36-'01_INPUTS'!$C$7+1)/7,0) -> 29 | L36: =ROUNDUP((J36-'01_INPUTS'!$C$7+1)/7,0) -> 32 | M36: =B36&"|"&F36 -> Site 04|Hypercare
B37: ='Sites Master'!$B$6 -> Site 05 | C37: ='Sites Master'!$A$6 -> Mexico | D37: ='Sites Master'!$C$6 -> 3 | E37: ='01_INPUTS'!$C$8 -> A | F37: {=INDEX('Implementation Phases'!$B$2:$B$9,G37)} -> Site Readiness | G37: =1 -> 1 | H37: {=IFERROR(_xlfn.XLOOKUP(1,('Implementation Phases'!$A$2:$A$65=D37)*('Implementation Phases'!$D$2:$D$65=E37)*('Implementation Phases'!$C$2:$C$65=G37),'Implementation Phases'!$E$2:$E$65),0)} -> 4 | I37: =INDEX($S$5:$S$19,MATCH(B37,$P$5:$P$19,0)) -> 46363 | J37: =IF(H37=0,I37,I37+H37*7-1) -> 46390 | K37: =ROUNDUP((I37-'01_INPUTS'!$C$7+1)/7,0) -> 17 | L37: =ROUNDUP((J37-'01_INPUTS'!$C$7+1)/7,0) -> 20 | M37: =B37&"|"&F37 -> Site 05|Site Readiness
B38: ='Sites Master'!$B$6 -> Site 05 | C38: ='Sites Master'!$A$6 -> Mexico | D38: ='Sites Master'!$C$6 -> 3 | E38: ='01_INPUTS'!$C$8 -> A | F38: {=INDEX('Implementation Phases'!$B$2:$B$9,G38)} -> Design Adaptation | G38: =2 -> 2 | H38: {=IFERROR(_xlfn.XLOOKUP(1,('Implementation Phases'!$A$2:$A$65=D38)*('Implementation Phases'!$D$2:$D$65=E38)*('Implementation Phases'!$C$2:$C$65=G38),'Implementation Phases'!$E$2:$E$65),0)} -> 1 | I38: =J37+1 -> 46391 | J38: =IF(H38=0,I38,I38+H38*7-1) -> 46397 | K38: =ROUNDUP((I38-'01_INPUTS'!$C$7+1)/7,0) -> 21 | L38: =ROUNDUP((J38-'01_INPUTS'!$C$7+1)/7,0) -> 21 | M38: =B38&"|"&F38 -> Site 05|Design Adaptation
B39: ='Sites Master'!$B$6 -> Site 05 | C39: ='Sites Master'!$A$6 -> Mexico | D39: ='Sites Master'!$C$6 -> 3 | E39: ='01_INPUTS'!$C$8 -> A | F39: {=INDEX('Implementation Phases'!$B$2:$B$9,G39)} -> Functional Review | G39: =3 -> 3 | H39: {=IFERROR(_xlfn.XLOOKUP(1,('Implementation Phases'!$A$2:$A$65=D39)*('Implementation Phases'!$D$2:$D$65=E39)*('Implementation Phases'!$C$2:$C$65=G39),'Implementation Phases'!$E$2:$E$65),0)} -> 1 | I39: =J38+1 -> 46398 | J39: =IF(H39=0,I39,I39+H39*7-1) -> 46404 | K39: =ROUNDUP((I39-'01_INPUTS'!$C$7+1)/7,0) -> 22 | L39: =ROUNDUP((J39-'01_INPUTS'!$C$7+1)/7,0) -> 22 | M39: =B39&"|"&F39 -> Site 05|Functional Review
B40: ='Sites Master'!$B$6 -> Site 05 | C40: ='Sites Master'!$A$6 -> Mexico | D40: ='Sites Master'!$C$6 -> 3 | E40: ='01_INPUTS'!$C$8 -> A | F40: {=INDEX('Implementation Phases'!$B$2:$B$9,G40)} -> UAT | G40: =4 -> 4 | H40: {=IFERROR(_xlfn.XLOOKUP(1,('Implementation Phases'!$A$2:$A$65=D40)*('Implementation Phases'!$D$2:$D$65=E40)*('Implementation Phases'!$C$2:$C$65=G40),'Implementation Phases'!$E$2:$E$65),0)} -> 1 | I40: =J39+1 -> 46405 | J40: =IF(H40=0,I40,I40+H40*7-1) -> 46411 | K40: =ROUNDUP((I40-'01_INPUTS'!$C$7+1)/7,0) -> 23 | L40: =ROUNDUP((J40-'01_INPUTS'!$C$7+1)/7,0) -> 23 | M40: =B40&"|"&F40 -> Site 05|UAT
B41: ='Sites Master'!$B$6 -> Site 05 | C41: ='Sites Master'!$A$6 -> Mexico | D41: ='Sites Master'!$C$6 -> 3 | E41: ='01_INPUTS'!$C$8 -> A | F41: {=INDEX('Implementation Phases'!$B$2:$B$9,G41)} -> Training | G41: =5 -> 5 | H41: {=IFERROR(_xlfn.XLOOKUP(1,('Implementation Phases'!$A$2:$A$65=D41)*('Implementation Phases'!$D$2:$D$65=E41)*('Implementation Phases'!$C$2:$C$65=G41),'Implementation Phases'!$E$2:$E$65),0)} -> 2 | I41: =J40+1 -> 46412 | J41: =IF(H41=0,I41,I41+H41*7-1) -> 46425 | K41: =ROUNDUP((I41-'01_INPUTS'!$C$7+1)/7,0) -> 24 | L41: =ROUNDUP((J41-'01_INPUTS'!$C$7+1)/7,0) -> 25 | M41: =B41&"|"&F41 -> Site 05|Training
...

Sheet 03_RESOURCES
AA1: ZONA DE CALCULO: detalle Site x Fase x Rol (join Schedule + Phase-Resource Allocation) - no editar
B2: SIMULADOR WMS - 03_RESOURCES (capacidad vs demanda de recursos) | AA2: Site | AB2: Fase | AC2: Rol | AD2: Consumo (capacidad) | AE2: Semana Inicio | AF2: Semana Fin | AG2: Recurso-semanas
AA3: ='Sites Master'!$B$2 -> Site 01 | AB3: ='Phase-Resource Allocation'!$B$64 -> Site Readiness | AC3: ='Phase-Resource Allocation'!$C$64 -> Infrastructure Lead | AD3: ='Phase-Resource Allocation'!$D$64 -> 1 | AE3: =IFERROR(INDEX('02_SCHEDULE'!$K$5:$K$124,MATCH(AA3&"|"&AB3,'02_SCHEDULE'!$M$5:$M$124,0)),0) -> 1 | AF3: =IFERROR(INDEX('02_SCHEDULE'!$L$5:$L$124,MATCH(AA3&"|"&AB3,'02_SCHEDULE'!$M$5:$M$124,0)),0) -> 4 | AG3: =AD3*(AF3-AE3+1) -> 4
B4: DISPONIBILIDAD POR ROL (fuente: 01_INPUTS) | AA4: ='Sites Master'!$B$2 -> Site 01 | AB4: ='Phase-Resource Allocation'!$B$65 -> Site Readiness | AC4: ='Phase-Resource Allocation'!$C$65 -> SAP Integrations Lead | AD4: ='Phase-Resource Allocation'!$D$65 -> 0.5 | AE4: =IFERROR(INDEX('02_SCHEDULE'!$K$5:$K$124,MATCH(AA4&"|"&AB4,'02_SCHEDULE'!$M$5:$M$124,0)),0) -> 1 | AF4: =IFERROR(INDEX('02_SCHEDULE'!$L$5:$L$124,MATCH(AA4&"|"&AB4,'02_SCHEDULE'!$M$5:$M$124,0)),0) -> 4 | AG4: =AD4*(AF4-AE4+1) -> 2
B5: Rol | C5: Disponible (usado) | AA5: ='Sites Master'!$B$2 -> Site 01 | AB5: ='Phase-Resource Allocation'!$B$66 -> Design Adaptation | AC5: ='Phase-Resource Allocation'!$C$66 -> Solution Architect | AD5: ='Phase-Resource Allocation'!$D$66 -> 1 | AE5: =IFERROR(INDEX('02_SCHEDULE'!$K$5:$K$124,MATCH(AA5&"|"&AB5,'02_SCHEDULE'!$M$5:$M$124,0)),0) -> 5 | AF5: =IFERROR(INDEX('02_SCHEDULE'!$L$5:$L$124,MATCH(AA5&"|"&AB5,'02_SCHEDULE'!$M$5:$M$124,0)),0) -> 5 | AG5: =AD5*(AF5-AE5+1) -> 1
B6: ='01_INPUTS'!$B$17 -> Solution Architect | C6: ='01_INPUTS'!$E$17 -> 1 | AA6: ='Sites Master'!$B$2 -> Site 01 | AB6: ='Phase-Resource Allocation'!$B$67 -> Design Adaptation | AC6: ='Phase-Resource Allocation'!$C$67 -> SAP Integrations Lead | AD6: ='Phase-Resource Allocation'!$D$67 -> 0.5 | AE6: =IFERROR(INDEX('02_SCHEDULE'!$K$5:$K$124,MATCH(AA6&"|"&AB6,'02_SCHEDULE'!$M$5:$M$124,0)),0) -> 5 | AF6: =IFERROR(INDEX('02_SCHEDULE'!$L$5:$L$124,MATCH(AA6&"|"&AB6,'02_SCHEDULE'!$M$5:$M$124,0)),0) -> 5 | AG6: =AD6*(AF6-AE6+1) -> 0.5
B7: ='01_INPUTS'!$B$18 -> Warehouse Manager Org A | C7: ='01_INPUTS'!$E$18 -> 1 | AA7: ='Sites Master'!$B$2 -> Site 01 | AB7: ='Phase-Resource Allocation'!$B$68 -> Design Adaptation | AC7: ='Phase-Resource Allocation'!$C$68 -> SAP Integrations Specialist | AD7: ='Phase-Resource Allocation'!$D$68 -> 0.5 | AE7: =IFERROR(INDEX('02_SCHEDULE'!$K$5:$K$124,MATCH(AA7&"|"&AB7,'02_SCHEDULE'!$M$5:$M$124,0)),0) -> 5 | AF7: =IFERROR(INDEX('02_SCHEDULE'!$L$5:$L$124,MATCH(AA7&"|"&AB7,'02_SCHEDULE'!$M$5:$M$124,0)),0) -> 5 | AG7: =AD7*(AF7-AE7+1) -> 0.5
B8: ='01_INPUTS'!$B$19 -> Project Manager Country B | C8: ='01_INPUTS'!$E$19 -> 1 | AA8: ='Sites Master'!$B$2 -> Site 01 | AB8: ='Phase-Resource Allocation'!$B$69 -> Design Adaptation | AC8: ='Phase-Resource Allocation'!$C$69 -> Azure Lead | AD8: ='Phase-Resource Allocation'!$D$69 -> 0.5 | AE8: =IFERROR(INDEX('02_SCHEDULE'!$K$5:$K$124,MATCH(AA8&"|"&AB8,'02_SCHEDULE'!$M$5:$M$124,0)),0) -> 5 | AF8: =IFERROR(INDEX('02_SCHEDULE'!$L$5:$L$124,MATCH(AA8&"|"&AB8,'02_SCHEDULE'!$M$5:$M$124,0)),0) -> 5 | AG8: =AD8*(AF8-AE8+1) -> 0.5
B9: ='01_INPUTS'!$B$20 -> Project Manager Country A | C9: ='01_INPUTS'!$E$20 -> 1 | AA9: ='Sites Master'!$B$2 -> Site 01 | AB9: ='Phase-Resource Allocation'!$B$70 -> Design Adaptation | AC9: ='Phase-Resource Allocation'!$C$70 -> Azure Specialist | AD9: ='Phase-Resource Allocation'!$D$70 -> 0.5 | AE9: =IFERROR(INDEX('02_SCHEDULE'!$K$5:$K$124,MATCH(AA9&"|"&AB9,'02_SCHEDULE'!$M$5:$M$124,0)),0) -> 5 | AF9: =IFERROR(INDEX('02_SCHEDULE'!$L$5:$L$124,MATCH(AA9&"|"&AB9,'02_SCHEDULE'!$M$5:$M$124,0)),0) -> 5 | AG9: =AD9*(AF9-AE9+1) -> 0.5
B10: ='01_INPUTS'!$B$21 -> Change Management Lead | C10: ='01_INPUTS'!$E$21 -> 2 | AA10: ='Sites Master'!$B$2 -> Site 01 | AB10: ='Phase-Resource Allocation'!$B$71 -> Design Adaptation | AC10: ='Phase-Resource Allocation'!$C$71 -> Testing Lead | AD10: ='Phase-Resource Allocation'!$D$71 -> 1 | AE10: =IFERROR(INDEX('02_SCHEDULE'!$K$5:$K$124,MATCH(AA10&"|"&AB10,'02_SCHEDULE'!$M$5:$M$124,0)),0) -> 5 | AF10: =IFERROR(INDEX('02_SCHEDULE'!$L$5:$L$124,MATCH(AA10&"|"&AB10,'02_SCHEDULE'!$M$5:$M$124,0)),0) -> 5 | AG10: =AD10*(AF10-AE10+1) -> 1
B11: ='01_INPUTS'!$B$22 -> Infrastructure Lead | C11: ='01_INPUTS'!$E$22 -> 2 | AA11: ='Sites Master'!$B$2 -> Site 01 | AB11: ='Phase-Resource Allocation'!$B$72 -> Design Adaptation | AC11: ='Phase-Resource Allocation'!$C$72 -> Functional Lead | AD11: ='Phase-Resource Allocation'!$D$72 -> 1 | AE11: =IFERROR(INDEX('02_SCHEDULE'!$K$5:$K$124,MATCH(AA11&"|"&AB11,'02_SCHEDULE'!$M$5:$M$124,0)),0) -> 5 | AF11: =IFERROR(INDEX('02_SCHEDULE'!$L$5:$L$124,MATCH(AA11&"|"&AB11,'02_SCHEDULE'!$M$5:$M$124,0)),0) -> 5 | AG11: =AD11*(AF11-AE11+1) -> 1
B12: ='01_INPUTS'!$B$23 -> Functional Lead | C12: ='01_INPUTS'!$E$23 -> 2 | AA12: ='Sites Master'!$B$2 -> Site 01 | AB12: ='Phase-Resource Allocation'!$B$73 -> Design Adaptation | AC12: ='Phase-Resource Allocation'!$C$73 -> Trainers | AD12: ='Phase-Resource Allocation'!$D$73 -> 1 | AE12: =IFERROR(INDEX('02_SCHEDULE'!$K$5:$K$124,MATCH(AA12&"|"&AB12,'02_SCHEDULE'!$M$5:$M$124,0)),0) -> 5 | AF12: =IFERROR(INDEX('02_SCHEDULE'!$L$5:$L$124,MATCH(AA12&"|"&AB12,'02_SCHEDULE'!$M$5:$M$124,0)),0) -> 5 | AG12: =AD12*(AF12-AE12+1) -> 1
B13: ='01_INPUTS'!$B$24 -> SAP Integrations Lead | C13: ='01_INPUTS'!$E$24 -> 1 | AA13: ='Sites Master'!$B$2 -> Site 01 | AB13: ='Phase-Resource Allocation'!$B$74 -> Design Adaptation | AC13: ='Phase-Resource Allocation'!$C$74 -> Infrastructure Lead | AD13: ='Phase-Resource Allocation'!$D$74 -> 1 | AE13: =IFERROR(INDEX('02_SCHEDULE'!$K$5:$K$124,MATCH(AA13&"|"&AB13,'02_SCHEDULE'!$M$5:$M$124,0)),0) -> 5 | AF13: =IFERROR(INDEX('02_SCHEDULE'!$L$5:$L$124,MATCH(AA13&"|"&AB13,'02_SCHEDULE'!$M$5:$M$124,0)),0) -> 5 | AG13: =AD13*(AF13-AE13+1) -> 1
